console.log("Inside Test");
throw "Test Failed From Manual Exception";

